W1119 00:05:34.058000 3675 torch/distributed/run.py:793] 
W1119 00:05:34.058000 3675 torch/distributed/run.py:793] *****************************************
W1119 00:05:34.058000 3675 torch/distributed/run.py:793] Setting OMP_NUM_THREADS environment variable for each process to be 1 in default, to avoid your system being overloaded, please further tune the variable for optimal performance in your application as needed. 
W1119 00:05:34.058000 3675 torch/distributed/run.py:793] *****************************************
total desired batch size: 524288
=> calculated gradient accumulation steps: 4
found 99 shards for split train
found 1 shards for split val
[rank0]: Traceback (most recent call last):
[rank0]:   File "/workspace/train_gpt2.py", line 76, in <module>
[rank0]:     checkpoint_path = sys.argv[1]
[rank0]: IndexError: list index out of range
[rank1]: Traceback (most recent call last):
[rank1]:   File "/workspace/train_gpt2.py", line 76, in <module>
[rank1]:     checkpoint_path = sys.argv[1]
[rank1]: IndexError: list index out of range
[rank0]:[W1119 00:05:45.784217324 ProcessGroupNCCL.cpp:1250] Warning: WARNING: process group has NOT been destroyed before we destruct ProcessGroupNCCL. On normal program exit, the application should call destroy_process_group to ensure that any pending NCCL operations have finished in this process. In rare cases this process can exit before this point and block the progress of another member of the process group. This constraint has always been present,  but this warning has only been added since PyTorch 2.4 (function operator())
W1119 00:05:45.454000 3675 torch/distributed/elastic/multiprocessing/api.py:897] Sending process 3755 closing signal SIGTERM
E1119 00:05:45.724000 3675 torch/distributed/elastic/multiprocessing/api.py:869] failed (exitcode: 1) local_rank: 0 (pid: 3754) of binary: /workspace/.venv/bin/python3
Traceback (most recent call last):
  File "/workspace/.venv/bin/torchrun", line 8, in <module>
    sys.exit(main())
  File "/workspace/.venv/lib/python3.10/site-packages/torch/distributed/elastic/multiprocessing/errors/__init__.py", line 355, in wrapper
    return f(*args, **kwargs)
  File "/workspace/.venv/lib/python3.10/site-packages/torch/distributed/run.py", line 919, in main
    run(args)
  File "/workspace/.venv/lib/python3.10/site-packages/torch/distributed/run.py", line 910, in run
    elastic_launch(
  File "/workspace/.venv/lib/python3.10/site-packages/torch/distributed/launcher/api.py", line 138, in __call__
    return launch_agent(self._config, self._entrypoint, list(args))
  File "/workspace/.venv/lib/python3.10/site-packages/torch/distributed/launcher/api.py", line 269, in launch_agent
    raise ChildFailedError(
torch.distributed.elastic.multiprocessing.errors.ChildFailedError: 
============================================================
train_gpt2.py FAILED
------------------------------------------------------------
Failures:
  <NO_OTHER_FAILURES>
------------------------------------------------------------
Root Cause (first observed failure):
[0]:
  time      : 2024-11-19_00:05:45
  host      : 775aae7f8145
  rank      : 0 (local_rank: 0)
  exitcode  : 1 (pid: 3754)
  error_file: <N/A>
  traceback : To enable traceback see: https://pytorch.org/docs/stable/elastic/errors.html
============================================================
Runpod config file not found, please run `runpodctl config` to create it
pod "cn0yefj8gu03ge" removed
